<robot name="TRR">

<!-- ===============================Color============================ -->
  <!-- Orange-->
  <material name="orange">
  <color rgba="1.0 0.5 0.0 1.0"/>
  </material>

  <!-- Blue--> 
  <material name="blue">
    <color rgba="0 0 0.8 1"/>
  </material>

  <!-- Yellow-->
  <material name="yellow">
    <color rgba="1 1 0 1"/>
  </material>

<!-- ===============================Component============================ -->
  <!-- Than -->
  <link name="base_link">
  </link>

  <!-- Khung -->
  <link name="frame_link">
    <visual>
      <geometry>
        <box size="0.2 0.3 0.1"/>
      </geometry>
      <origin xyz="0 0 0" rpy="0.0 0.0 0.0"/>
      <material name="orange"/>
    </visual>
    <inertial>
        <mass value="2.0"/>
        <origin xyz="0.0 0.0 0.0"/>
        <inertia ixx="0.0" ixy="0.0" ixz="0.0" iyy="0.0" iyz="0.0" izz="0.0"/>
    </inertial>
    <collision>
      <geometry>
        <box size="0.2 0.3 0.1"/>
      </geometry>
      <origin xyz="0 0 0" rpy="0.0 0.0 0.0"/>
    </collision>
  </link>

  <!-- Khop noi than - khung -->
  <joint name="base_joint" type="fixed">
      <parent link="base_link"/>
      <child link="frame_link"/>
      <origin xyz="0.0 0.0 0.0" rpy="0.0 0.0 0.0"/>
  </joint>

  <!-- Banh phai truoc-->
  <link name="right_front_wheel_link">
    <visual>
      <geometry>
        <cylinder radius="0.05" length="0.03"/>
      </geometry>
      <origin rpy="0 0 0" xyz="0 0 0"/>
      <material name="yellow"/>
    </visual>
    <inertial>
        <mass value="2.0"/>
        <origin xyz="0.0 0.0 0.0"/>
        <inertia ixx="0.1" ixy="0.0" ixz="0.0" iyy="0.1" iyz="0.0" izz="0.1"/>
    </inertial>
    <collision>
      <geometry>
        <cylinder radius="0.05" length="0.03"/>
      </geometry>
      <origin rpy="0 0 0" xyz="0 0 0"/>
    </collision>
  </link>

  <!-- Khop noi than - banh phai truoc -->
  <joint name="right_front_wheel_joint" type="continuous">
    <parent link="base_link"/>
    <child link="right_front_wheel_link"/>
    <origin rpy="0 1.57075 1.57075" xyz="0 0.18 -0.05"/>
    <axis xyz="0.0 0.0 1.0"/>
  </joint>

  <!-- Banh trai truoc-->
    <link name="left_front_wheel_link">
    <visual>
      <geometry>
        <cylinder radius="0.05" length="0.03"/>
      </geometry>
      <origin rpy="0 0 0" xyz="0 0 0"/>
      <material name="yellow"/>
    </visual>
    <inertial>
        <mass value="5.0"/>
        <origin xyz="0.0 0.0 0.0"/>
        <inertia ixx="0.1" ixy="0.0" ixz="0.0" iyy="0.1" iyz="0.0" izz="0.1"/>
    </inertial>
    <collision>
      <geometry>
        <cylinder radius="0.05" length="0.03"/>
      </geometry>
      <origin rpy="0 0 0" xyz="0 0 0"/>
    </collision>
  </link>

  <!-- Khop noi than - banh trai truoc -->
  <joint name="left_front_wheel_joint" type="continuous">
    <parent link="base_link"/>
    <child link="left_front_wheel_link"/>
    <origin rpy="3.1415 1.57075 1.57075" xyz="0 -0.18 -0.05"/>
    <axis xyz="0.0 0.0 1.0"/>
  </joint>

  <!-- Banh ban phai-->
  <link name="right_shoot_wheel_link">
    <visual>
      <geometry>
        <cylinder radius="0.0325" length="0.027"/>
      </geometry>
      <origin rpy="0 0 0" xyz="0 0 0"/>
      <material name="yellow"/>
    </visual>
    <inertial>
        <mass value="0.2"/>
        <origin xyz="0.0 0.0 0.0"/>
        <inertia ixx="0.1" ixy="0.0" ixz="0.0" iyy="0.1" iyz="0.0" izz="0.1"/>
    </inertial>
    <collision>
      <geometry>
        <cylinder radius="0.0325" length="0.027"/>
      </geometry>
      <origin rpy="0 0 0" xyz="0 0 0"/>
    </collision>
  </link>

    <!-- Khop noi than - banh ban phai-->
  <joint name="right_shoot_wheel_joint" type="continuous">
    <parent link="base_link"/>
    <child link="right_shoot_wheel_link"/>
    <origin rpy="0 -0.785375 0" xyz="-0.25 0.06 -0.05"/>
    <axis xyz="0.0 0.0 1.0"/>
  </joint>

  <!-- Banh ban trai-->
  <link name="left_shoot_wheel_link">
    <visual>
      <geometry>
        <cylinder radius="0.0325" length="0.027"/>
      </geometry>
      <origin rpy="0 0 0" xyz="0 0 0"/>
      <material name="yellow"/>
    </visual>
    <inertial>
        <mass value="0.2"/>
        <origin xyz="0.0 0.0 0.0"/>
        <inertia ixx="0.1" ixy="0.0" ixz="0.0" iyy="0.1" iyz="0.0" izz="0.1"/>
    </inertial>
    <collision>
      <geometry>
        <cylinder radius="0.0325" length="0.027"/>
      </geometry>
      <origin rpy="0 0 0" xyz="0 0 0"/>
    </collision>
  </link>

  <!-- Khop noi than - banh ban trai -->
  <joint name="left_shoot_wheel_joint" type="continuous">
    <parent link="base_link"/>
    <child link="left_shoot_wheel_link"/>
    <origin rpy="3.1415 -0.785375 0" xyz="-0.25 -0.06 -0.05"/>
    <axis xyz="0.0 0.0 1.0"/>
  </joint>

  <!-- De sau -->
  <link name="back_base_link">
    <visual>
      <geometry>
        <box size="0.4 0.3 0.02"/>
      </geometry>
      <origin rpy="0 0 0" xyz="0.3 0 -0.05"/>
      <material name="blue"/>
    </visual>
    <inertial>
        <mass value="5"/>
        <origin xyz="0.0 0.0 0.0"/>
        <inertia ixx="0.1" ixy="0" ixz="0" iyy="0.1" iyz="0" izz="0.1"/>
    </inertial>
    <collision>
      <geometry>
        <box size="0.4 0.3 0.02"/>
      </geometry>
      <origin rpy="0 0 0" xyz="0.3 0 -0.05"/>
    </collision>
  </link>

  <!-- Khop noi than - de sau -->
  <joint name="back_base_joint" type="fixed">
    <parent link="base_link"/>
    <child link="back_base_link"/>
  </joint>

    <!-- Canh 1 de sau -->
  <link name="back_base_edge_1_link">
    <visual>
      <geometry>
        <box size="0.1 0.3 0.02"/>
      </geometry>
      <origin rpy="0 1.57075 0" xyz="0.5 0 0.0"/>
      <material name="blue"/>
    </visual>
    <inertial>
        <mass value="5"/>
        <origin xyz="0.0 0.0 0.0"/>
        <inertia ixx="0.1" ixy="0" ixz="0" iyy="0.1" iyz="0" izz="0.1"/>
    </inertial>
    <collision>
      <geometry>
        <box size="0.1 0.3 0.02"/>
      </geometry>
      <origin rpy="0 1.57075 0" xyz="0.5 0 0.0"/>
    </collision>
  </link>

  <!-- Khop noi than - canh 1 de sau -->
  <joint name="back_base_edge_1_joint" type="fixed">
    <parent link="back_base_link"/>
    <child link="back_base_edge_1_link"/>
  </joint>

      <!-- Canh 2 de sau -->
  <link name="back_base_edge_2_link">
    <visual>
      <geometry>
        <box size="0.4 0.1 0.02"/>
      </geometry>
      <origin rpy="1.57075 0 0" xyz="0.3 0.15 0.0"/>
      <material name="blue"/>
    </visual>
    <inertial>
        <mass value="5"/>
        <origin xyz="0.0 0.0 0.0"/>
        <inertia ixx="0.1" ixy="0" ixz="0" iyy="0.1" iyz="0" izz="0.1"/>
    </inertial>
    <collision>
      <geometry>
        <box size="0.4 0.1 0.02"/>
      </geometry>
      <origin rpy="1.57075 0 0" xyz="0.3 0.15 0.0"/>
    </collision>
  </link>

  <!-- Khop noi than - canh 2 de sau -->
  <joint name="back_base_edge_2_joint" type="fixed">
    <parent link="back_base_link"/>
    <child link="back_base_edge_2_link"/>
  </joint>

      <!-- Canh 3 de sau -->
  <link name="back_base_edge_3_link">
    <visual>
      <geometry>
        <box size="0.4 0.1 0.02"/>
      </geometry>
      <origin rpy="1.57075 0 0" xyz="0.3 -0.15 0.0"/>
      <material name="blue"/>
    </visual>
    <inertial>
        <mass value="5"/>
        <origin xyz="0.0 0.0 0.0"/>
        <inertia ixx="0.1" ixy="0" ixz="0" iyy="0.1" iyz="0" izz="0.1"/>
    </inertial>
    <collision>
      <geometry>
        <box size="0.4 0.1 0.02"/>
      </geometry>
      <origin rpy="1.57075 0 0" xyz="0.3 -0.15 0.0"/>
    </collision>
  </link>

  <!-- Khop noi than - canh 3 de sau -->
  <joint name="back_base_edge_3_joint" type="fixed">
    <parent link="back_base_link"/>
    <child link="back_base_edge_3_link"/>
  </joint>

  <!-- Banh mat trau sau phai-->
  <link name="right_back_caster_wheel_link">
    <visual>
      <geometry>
        <sphere radius="0.025"/>
      </geometry>
      <origin rpy="0 0 0" xyz="0 0 0"/>
      <material name="yellow"/>
    </visual>
    <inertial>
        <mass value="1"/>
        <origin xyz="0.0 0.0 0.0"/>
        <inertia ixx="1e-6" ixy="0" ixz="0" iyy="1e-6" iyz="0" izz="1e-6"/>
    </inertial>
    <collision>
      <geometry>
        <sphere radius="0.025"/>
      </geometry>
      <origin rpy="0 0 0" xyz="0 0 0"/>
    </collision>
  </link>

  <!-- Khop noi de sau - banh mat trau sau phai -->
  <joint name="right_back_caster_wheel_joint" type="continuous">
    <parent link="back_base_link"/>
    <child link="right_back_caster_wheel_link"/>
    <origin rpy="0 0 0" xyz="0.4 0.1 -0.075"/>
    <axis xyz="1.0 1.0 1.0"/>
  </joint>

  <!-- Banh mat trau sau trai-->
  <link name="left_back_caster_wheel_link">
    <visual>
      <geometry>
        <sphere radius="0.025"/>
      </geometry>
      <origin rpy="0 0 0" xyz="0 0 0"/>
      <material name="yellow"/>
    </visual>
    <inertial>
        <mass value="1"/>
        <origin xyz="0.0 0.0 0.0"/>
        <inertia ixx="1e-6" ixy="0" ixz="0" iyy="1e-6" iyz="0" izz="1e-6"/>
    </inertial>
    <collision>
      <geometry>
        <sphere radius="0.025"/>
      </geometry>
      <origin rpy="0 0 0" xyz="0 0 0"/>
    </collision>
  </link>

  <!-- Khop noi de sau - banh mat trau sau trai -->
  <joint name="left_back_caster_wheel_joint" type="continuous">
    <parent link="back_base_link"/>
    <child link="left_back_caster_wheel_link"/>
    <origin rpy="3.1415 0 0" xyz="0.4 -0.1 -0.075"/>
    <axis xyz="1.0 1.0 1.0"/>
  </joint>

<!-- ===============================Transmission============================ -->
  <!-- Right Front Wheel Transmission -->
  <transmission name="tran1">
      <type>transmission_interface/SimpleTransmission</type>
      <joint name="right_front_wheel_joint">
          <hardwareInterface>hardware_interface/EffortJointInterface</hardwareInterface>
      </joint>
      <actuator name="motor1">
          <hardwareInterface>hardware_interface/EffortJointInterface</hardwareInterface>
          <mechanicalReduction>1</mechanicalReduction>
      </actuator>
  </transmission>

  <!-- Left Front Wheel Transmission -->
  <transmission name="tran2">
      <type>transmission_interface/SimpleTransmission</type>
      <joint name="left_front_wheel_joint">
          <hardwareInterface>hardware_interface/EffortJointInterface</hardwareInterface>
      </joint>
      <actuator name="motor2">
          <hardwareInterface>hardware_interface/EffortJointInterface</hardwareInterface>
          <mechanicalReduction>1</mechanicalReduction>
      </actuator>
  </transmission>

    <!-- Right Shoot Wheel Transmission -->
  <transmission name="tran3">
      <type>transmission_interface/SimpleTransmission</type>
      <joint name="right_shoot_wheel_joint">
          <hardwareInterface>hardware_interface/EffortJointInterface</hardwareInterface>
      </joint>
      <actuator name="motor3">
          <hardwareInterface>hardware_interface/EffortJointInterface</hardwareInterface>
          <mechanicalReduction>1</mechanicalReduction>
      </actuator>
  </transmission>

  <!-- Left Shoot Wheel Transmission -->
  <transmission name="tran4">
      <type>transmission_interface/SimpleTransmission</type>
      <joint name="left_shoot_wheel_joint">
          <hardwareInterface>hardware_interface/EffortJointInterface</hardwareInterface>
      </joint>
      <actuator name="motor4">
          <hardwareInterface>hardware_interface/EffortJointInterface</hardwareInterface>
          <mechanicalReduction>1</mechanicalReduction>
      </actuator>
  </transmission>

<!-- ===============================Gazebo============================ -->
  <!-- Gazebo Visual Properties -->
  <gazebo reference="frame_link">
      <material>Gazebo/Orange</material>
  </gazebo>
  <gazebo reference="right_front_wheel_link">
      <material>Gazebo/Yellow</material>
  </gazebo>
  <gazebo reference="left_front_wheel_link">
      <material>Gazebo/Yellow</material>
  </gazebo>
  <gazebo reference="left_shoot_wheel_link">
      <material>Gazebo/Yellow</material>
  </gazebo>
  <gazebo reference="right_shoot_wheel_link">
      <material>Gazebo/Yellow</material>
  </gazebo>
  <gazebo reference="back_base_link">
      <material>Gazebo/Blue</material>
  </gazebo>
  <gazebo reference="back_base_edge_1_link">
      <material>Gazebo/Blue</material>
  </gazebo>
  <gazebo reference="back_base_edge_2_link">
      <material>Gazebo/Blue</material>
  </gazebo>
  <gazebo reference="back_base_edge_3_link">
      <material>Gazebo/Blue</material>
  </gazebo>
  <gazebo reference="right_back_caster_wheel_link">
      <material>Gazebo/Yellow</material>
  </gazebo>
  <gazebo reference="left_back_caster_wheel_link">
      <material>Gazebo/Yellow</material>
  </gazebo>


  <!-- Gazebo ROS Control Plugin -->
  <gazebo>
      <plugin name="gazebo_ros_control" filename="libgazebo_ros_control.so">
          <robotNamespace>/my_TRR</robotNamespace>
      </plugin>
  </gazebo>

</robot>