<!-- ======================================== Author: Huu Chi ========================================  -->

<!-- ================================== Tennis ball Retrieval Robot =================================== -->
<robot name="TRR">

<!-- ============================================= Colors ============================================= -->
  <!-- Orange-->
  <material name="orange">
    <color rgba="1.0 0.5 0.0 1.0"/>
  </material>

  <!-- Blue--> 
  <material name="blue">
    <color rgba="0 0 0.8 1"/>
  </material>

  <!-- Yellow-->
  <material name="yellow">
    <color rgba="1 1 0 1"/>
  </material>

  <!-- Purple-->
  <material name="purple">
    <color rgba="1 0 1 1"/>
  </material>


<!-- ============================================= Components ============================================ -->
  <!-- Base-->
  <link name="base_link">
  </link>

  <!-- Frame-->
  <link name="frame_link">
    <visual>
      <material name="blue"/>
      <geometry>
        <mesh filename="package://my_robot/meshes/base2.stl" scale="0.001 0.001 0.001"/>
      </geometry>
      <origin xyz="0 0 0" rpy="0 0.0 3.1415"/>
    </visual>

    <collision>
      <geometry>
        <mesh filename="package://my_robot/meshes/base2.stl" scale="0.001 0.001 0.001"/>
      </geometry>
      <origin xyz="0 0 0" rpy="0 0.0 3.1415"/>
    </collision>

    <inertial>
      <mass value="20"/>
      <inertia ixx="1.0" ixy="0.0" ixz="0.0" iyy="1.0" iyz="0.0" izz="1.0"/>
      <origin xyz="-0.1 0 0" rpy="0.0 0.0 0.0"/>
    </inertial>
  </link>
  
  <!-- Base => Frame -->
  <joint name="frame_joint" type="fixed">
    <parent link="base_link"/>
    <child link="frame_link"/>
  </joint>

  <!-- Left active wheel-->
  <link name="left_active_wheel_link">
    <visual>
      <material name="yellow"/>
      <geometry>
        <mesh filename="package://my_robot/meshes/main_wheel.stl" scale="0.001 0.001 0.001"/>
      </geometry>
    </visual>

    <collision>
      <geometry>
        <mesh filename="package://my_robot/meshes/main_wheel.stl" scale="0.001 0.001 0.001"/>
      </geometry>
    </collision>

    <inertial>
        <mass value="0.18"/>
        <inertia ixx="0.1" ixy="0.0" ixz="0.0" iyy="0.1" iyz="0.0" izz="0.1"/>
    </inertial>
  </link>

  <!-- Frame => Left active wheel -->
  <joint name="left_active_wheel_joint" type="continuous">
    <parent link="frame_link"/> 
    <child link="left_active_wheel_link"/>
    <origin xyz="-0.15 -0.187 0.0225" rpy="0 0.0 0.0"/>
    <axis xyz="0 1 0"/>
  </joint>

  <!-- Right active wheel-->
  <link name="right_active_wheel_link">
    <visual>
      <material name="yellow"/>
      <geometry>
        <mesh filename="package://my_robot/meshes/main_wheel.stl" scale="0.001 0.001 0.001"/>
      </geometry>
    </visual>

    <collision>
      <geometry>
        <mesh filename="package://my_robot/meshes/main_wheel.stl" scale="0.001 0.001 0.001"/>
      </geometry>
    </collision>

    <inertial>
        <mass value="0.18"/>
        <inertia ixx="0.1" ixy="0.0" ixz="0.0" iyy="0.1" iyz="0.0" izz="0.1"/>
    </inertial>
  </link>

  <!-- Frame => Right active wheel -->
  <joint name="right_active_wheel_joint" type="continuous">
    <parent link="frame_link"/> 
    <child link="right_active_wheel_link"/>
    <origin xyz="-0.15 0.157 0.0225" rpy="0 0.0 0.0"/>
    <axis xyz="0 1 0"/>
  </joint>

    <!-- Base left oriented wheel-->
  <link name="base_left_oriented_wheel_link">
    <visual>
      <material name="orange"/>
      <geometry>
        <mesh filename="package://my_robot/meshes/oriented_link2.stl" scale="0.001 0.001 0.001"/>
      </geometry>
      <origin xyz="0 0 0" rpy="-1.57075 0.0 0.0"/>
    </visual>

    <collision>
      <geometry>
        <mesh filename="package://my_robot/meshes/oriented_link2.stl" scale="0.001 0.001 0.001"/>
      </geometry>
      <origin xyz="0 0 0" rpy="-1.57075 0.0 0.0"/>
    </collision>

    <inertial>
        <mass value="0.016"/>
        <inertia ixx="1e-6" ixy="0.0" ixz="0.0" iyy="1e-6" iyz="0.0" izz="1e-6"/>
    </inertial>
  </link>

  <!-- Frame => Base left oriented wheel -->
  <joint name="base_left_oriented_wheel_joint" type="continuous">
    <parent link="frame_link"/> 
    <child link="base_left_oriented_wheel_link"/>
    <origin xyz="0.233376 -0.0825 0" rpy="0 0.0 0.0"/>
    <axis xyz="0 0 1"/>
  </joint>

  <!-- Left oriented wheel-->
  <link name="left_oriented_wheel_link">
    <visual>
      <material name="orange"/>
      <geometry>
        <mesh filename="package://my_robot/meshes/oriented_wheel.stl" scale="0.001 0.001 0.001"/>
      </geometry>
    </visual>

    <collision>
      <geometry>
        <mesh filename="package://my_robot/meshes/oriented_wheel.stl" scale="0.001 0.001 0.001"/>
      </geometry>
    </collision>

    <inertial>
        <mass value="0.016"/>
        <inertia ixx="1e-6" ixy="0.0" ixz="0.0" iyy="1e-6" iyz="0.0" izz="1e-6"/>
    </inertial>
  </link>

  <!-- Base left oriented wheel => Left oriented wheel -->
  <joint name="left_oriented_wheel_joint" type="continuous">
    <parent link="base_left_oriented_wheel_link"/> 
    <child link="left_oriented_wheel_link"/>
    <origin xyz="0 -0.0055 -0.015" rpy="0 0.0 0"/>
    <axis xyz="0 1 0"/>
  </joint>

  <!-- Base right oriented wheel-->
  <link name="base_right_oriented_wheel_link">
    <visual>
      <material name="orange"/>
      <geometry>
        <mesh filename="package://my_robot/meshes/oriented_link2.stl" scale="0.001 0.001 0.001"/>
      </geometry>
      <origin xyz="0 0 0" rpy="-1.57075 0.0 0.0"/>
    </visual>

    <collision>
      <geometry>
        <mesh filename="package://my_robot/meshes/oriented_link2.stl" scale="0.001 0.001 0.001"/>
      </geometry>
    </collision>

    <inertial>
        <mass value="0.016"/>
        <inertia ixx="1e-6" ixy="0" ixz="0" iyy="1e-6" iyz="0.0" izz="1e-6"/>
      <origin xyz="0 0 0" rpy="-1.57075 0.0 0.0"/>
    </inertial>
  </link>

  <!-- Frame => Base right oriented wheel -->
  <joint name="base_right_oriented_wheel_joint" type="continuous">
    <parent link="frame_link"/> 
    <child link="base_right_oriented_wheel_link"/>
    <origin xyz="0.233376 0.0825 0" rpy="0 0.0 0.0"/>
    <axis xyz="0 0 1"/>
  </joint>

  <!-- Right oriented wheel-->
  <link name="right_oriented_wheel_link">
    <visual>
      <material name="orange"/>
      <geometry>
        <mesh filename="package://my_robot/meshes/oriented_wheel.stl" scale="0.001 0.001 0.001"/>
      </geometry>
    </visual>

    <collision>
      <geometry>
        <mesh filename="package://my_robot/meshes/oriented_wheel.stl" scale="0.001 0.001 0.001"/>
      </geometry>
    </collision>

    <inertial>
        <mass value="0.016"/>
        <inertia ixx="1e-6" ixy="0.0" ixz="0.0" iyy="1e-6" iyz="0.0" izz="1e-6"/>
    </inertial>
  </link>

  <!-- Base right oriented wheel => Right orriented wheel -->
  <joint name="right_oriented_wheel_joint" type="continuous">
    <parent link="base_right_oriented_wheel_link"/> 
    <child link="right_oriented_wheel_link"/>
    <origin xyz="0 -0.0055 -0.015" rpy="0 0.0 0"/>
    <axis xyz="0 1 0"/>
  </joint>

  <!-- Left shooting wheel-->
  <link name="left_shooting_wheel_link">
    <visual>
      <origin rpy="0 0 0" xyz="0 0 0"/>
      <material name="orange"/>
      <geometry>
        <mesh filename="package://my_robot/meshes/shooting_wheel.stl" scale="0.001 0.001 0.001"/>
      </geometry>
    </visual>

    <collision>
      <geometry>
        <mesh filename="package://my_robot/meshes/shooting_wheel.stl" scale="0.001 0.001 0.001"/>
      </geometry>
    </collision>

    <inertial>
        <mass value="0.1"/>
        <inertia ixx="0.1" ixy="0.0" ixz="0.0" iyy="0.1" iyz="0.0" izz="0.1"/>
    </inertial>
  </link>

  <!-- Frame => Left shooting wheel-->
  <joint name="left_shooting_wheel_joint" type="continuous">
    <parent link="frame_link"/> 
    <child link="left_shooting_wheel_link"/>
    <origin xyz="-0.315 -0.032 0.07" rpy="0 0 0"/>
        <axis xyz="0 1 0"/>
  </joint>

  <!-- Right shooting wheel-->
  <link name="right_shooting_wheel_link">
    <visual>
      <origin rpy="0 0 0" xyz="0 0 0"/>
      <material name="orange"/>
      <geometry>
        <mesh filename="package://my_robot/meshes/shooting_wheel.stl" scale="0.001 0.001 0.001"/>
      </geometry>
    </visual>

    <collision>
      <geometry>
        <mesh filename="package://my_robot/meshes/shooting_wheel.stl" scale="0.001 0.001 0.001"/>
      </geometry>
    </collision>

    <inertial>
        <mass value="0.1"/>
        <inertia ixx="0.1" ixy="0.0" ixz="0.0" iyy="0.1" iyz="0.0" izz="0.1"/>
    </inertial>
  </link>

  <!-- Frame => Right shooting wheel-->
  <joint name="right_shooting_wheel_joint" type="continuous">
    <parent link="frame_link"/> 
    <child link="right_shooting_wheel_link"/>
    <origin xyz="-0.315 0.005 0.07" rpy="0 0 0"/>
        <axis xyz="0 1 0"/>
  </joint>

  <!-- Camera Link -->
  <link name="camera_link">
    <visual>
      <origin rpy="0 0 0" xyz="0 0 0"/>
      <material name="purple"/>
      <geometry>
        <box size="0.003 0.03 0.03"/>
      </geometry>
    </visual>

    <collision>
      <geometry>
        <box size="0.03 0.03 0.003"/>
      </geometry>
    </collision>

    <inertial>
      <mass value="0.0024" />
      <inertia ixx="1e-6" ixy="0" ixz="0" iyy="1e-6" iyz="0" izz="1e-6" />
    </inertial>

  </link>

  <!-- Camera Joint (Fixed) -->
  <joint name="camera_joint" type="fixed">
      <parent link="frame_link"/>
      <child link="camera_link"/>
      <origin xyz="-0.38 0.0 0.07" rpy="0.0 0.52358 3.1415"/>
  </joint>  

<!-- ============================================= Transmission ============================================ -->
  <!-- Right Front Wheel Transmission -->
  <transmission name="tran1">
      <type>transmission_interface/SimpleTransmission</type>
      <joint name="left_active_wheel_joint">
          <hardwareInterface>hardware_interface/EffortJointInterface</hardwareInterface>
      </joint>
      <actuator name="motor1">
          <hardwareInterface>hardware_interface/EffortJointInterface</hardwareInterface>
          <mechanicalReduction>1</mechanicalReduction>
      </actuator>
  </transmission>

  <!-- Left Front Wheel Transmission -->
  <transmission name="tran2">
      <type>transmission_interface/SimpleTransmission</type>
      <joint name="right_active_wheel_joint">
          <hardwareInterface>hardware_interface/EffortJointInterface</hardwareInterface>
      </joint>
      <actuator name="motor2">
          <hardwareInterface>hardware_interface/EffortJointInterface</hardwareInterface>
          <mechanicalReduction>1</mechanicalReduction>
      </actuator>
  </transmission>

  <!-- Right Shoot Wheel Transmission -->
  <transmission name="tran3">
      <type>transmission_interface/SimpleTransmission</type>
      <joint name="left_shooting_wheel_joint">
          <hardwareInterface>hardware_interface/EffortJointInterface</hardwareInterface>
      </joint>
      <actuator name="motor3">
          <hardwareInterface>hardware_interface/EffortJointInterface</hardwareInterface>
          <mechanicalReduction>1</mechanicalReduction>
      </actuator>
  </transmission>

  <!-- Left Shoot Wheel Transmission -->
  <transmission name="tran4">
      <type>transmission_interface/SimpleTransmission</type>
      <joint name="right_shooting_wheel_joint">
          <hardwareInterface>hardware_interface/EffortJointInterface</hardwareInterface>
      </joint>
      <actuator name="motor4">
          <hardwareInterface>hardware_interface/EffortJointInterface</hardwareInterface>
          <mechanicalReduction>1</mechanicalReduction>
      </actuator>
  </transmission>

<!-- ================================================== Gazebo ====================================================== -->
  <!-- Gazebo Visual Properties -->
  <gazebo reference="frame_link">
      <material>Gazebo/Blue</material>
  </gazebo>
  <gazebo reference="left_active_wheel_link">
      <material>Gazebo/Yellow</material>
  </gazebo>
  <gazebo reference="right_active_wheel_link">
      <material>Gazebo/Yellow</material>
  </gazebo>
  <gazebo reference="base_left_oriented_wheel_link">
      <material>Gazebo/Orange</material>
  </gazebo>
  <gazebo reference="base_right_oriented_wheel_link">
      <material>Gazebo/Orange</material>
  </gazebo>
  <gazebo reference="left_oriented_wheel_link">
      <material>Gazebo/Orange</material>
  </gazebo>
  <gazebo reference="right_oriented_wheel_link">
      <material>Gazebo/Orange</material>
  </gazebo>
  <gazebo reference="left_shooting_wheel_link">
      <material>Gazebo/Orange</material>
  </gazebo>
  <gazebo reference="right_shooting_wheel_link">
      <material>Gazebo/Orange</material>
  </gazebo>

  <!-- Camera Sensor -->
  <gazebo reference="camera_link">
    <material>Gazebo/Purple</material>
    <sensor type="camera" name="camera1">
      <update_rate>30.0</update_rate>
      <camera name="head">
        <horizontal_fov>1.3962634</horizontal_fov>
        <image>
          <width>640</width>
          <height>480</height>
          <format>R8G8B8</format>
        </image>
        <clip>
          <near>0.02</near>
          <far>300</far>
        </clip>
        <noise>
          <type>gaussian</type>
          <mean>0.0</mean>
          <stddev>0.007</stddev>
        </noise>
      </camera>
      <plugin name="camera_controller" filename="libgazebo_ros_camera.so">
        <alwaysOn>true</alwaysOn>
        <updateRate>0.0</updateRate>
        <cameraName>my_robot/camera1</cameraName>
        <imageTopicName>image_raw</imageTopicName>
        <cameraInfoTopicName>camera_info</cameraInfoTopicName>
        <frameName>camera_link</frameName>
        <hackBaseline>0.07</hackBaseline>
        <distortionK1>0.0</distortionK1>
        <distortionK2>0.0</distortionK2>
        <distortionK3>0.0</distortionK3>
        <distortionT1>0.0</distortionT1>
        <distortionT2>0.0</distortionT2>
      </plugin>
    </sensor>
  </gazebo>

  <!-- Gazebo ROS Control Plugin -->
  <gazebo>
      <plugin name="gazebo_ros_control" filename="libgazebo_ros_control.so">
          <robotNamespace>/my_TRR</robotNamespace>
      </plugin>
  </gazebo>

</robot>